Workbook

Sheet Cover
A1: B2B DATA ENGINEERING PLATFORM
A2: Test Case Register (annex to Test Document)
A4: Version | B4: 1.1
A5: Prepared by | B5: Syed Kazim Raza
A6: Reviewed by | B6: [Team Lead]
A7: Date | B7: 30/09/2026
A8: Document ID | B8: B2B-DEP-08b
A9: How to use | B9: One row per test case. Expected result for SQL checks is normally '0 rows'. Status: Pass / Fail / Blocked / Not Run.

Sheet Summary
A1: Level | B1: Planned | C1: Executed | D1: Passed | E1: Failed | F1: Blocked | G1: Pass %
A2: Unit | B2: =COUNTA('Unit_Tests'!A2:A500) | C2: =COUNTIF('Unit_Tests'!J2:J500,"Pass")+COUNTIF('Unit_Tests'!J2:J500,"Fail") | D2: =COUNTIF('Unit_Tests'!J2:J500,"Pass") | E2: =COUNTIF('Unit_Tests'!J2:J500,"Fail") | F2: =COUNTIF('Unit_Tests'!J2:J500,"Blocked") | G2: =IFERROR(D2/C2,0)
A3: Integration | B3: =COUNTA('Integration_Tests'!A2:A500) | C3: =COUNTIF('Integration_Tests'!J2:J500,"Pass")+COUNTIF('Integration_Tests'!J2:J500,"Fail") | D3: =COUNTIF('Integration_Tests'!J2:J500,"Pass") | E3: =COUNTIF('Integration_Tests'!J2:J500,"Fail") | F3: =COUNTIF('Integration_Tests'!J2:J500,"Blocked") | G3: =IFERROR(D3/C3,0)
A4: KPI Validation | B4: =COUNTA('KPI_Validation'!A2:A500) | C4: =COUNTIF('KPI_Validation'!H2:H500,"Pass")+COUNTIF('KPI_Validation'!H2:H500,"Fail") | D4: =COUNTIF('KPI_Validation'!H2:H500,"Pass") | E4: =COUNTIF('KPI_Validation'!H2:H500,"Fail") | F4: =COUNTIF('KPI_Validation'!H2:H500,"Blocked") | G4: =IFERROR(D4/C4,0)
A5: Total | B5: =SUM(B2:B4) | C5: =SUM(C2:C4) | D5: =SUM(D2:D4) | E5: =SUM(E2:E4) | F5: =SUM(F2:F4) | G5: =IFERROR(D5/C5,0)

Sheet Unit_Tests
A1: Test ID | B1: Level | C1: Layer | D1: Object Under Test | E1: Test Type | F1: Description | G1: Test Script / File | H1: Expected Result | I1: Actual Result | J1: Status | K1: Executed On | L1: Evidence | M1: Defect ID
A2: UT-001 | B2: Unit | C2: Intermediate | D2: intermediate.categories | E2: Completeness | F2: Null category ids | G2: postgresql/intermediate/tests/Test_categories.sql (TEST 1) | H2: 0 rows | I2: 0 rows | J2: Pass | K2: 30/09/2026
A3: UT-002 | B3: Unit | C3: Intermediate | D3: intermediate.categories | E3: Uniqueness | F3: Duplicate category ids | G3: postgresql/intermediate/tests/Test_categories.sql (TEST 2) | H3: 0 rows | I3: 0 rows | J3: Pass | K3: 30/09/2026
A4: UT-003 | B4: Unit | C4: Intermediate | D4: intermediate.categories | E4: Uniqueness | F4: Duplicate category names | G4: postgresql/intermediate/tests/Test_categories.sql (TEST 3) | H4: 0 rows | I4: 0 rows | J4: Pass | K4: 30/09/2026
A5: UT-004 | B5: Unit | C5: Intermediate | D5: intermediate.categories | E5: Completeness | F5: Required text fields | G5: postgresql/intermediate/tests/Test_categories.sql (TEST 4) | H5: 0 rows | I5: 0 rows | J5: Pass | K5: 30/09/2026
A6: UT-005 | B6: Unit | C6: Intermediate | D6: intermediate.categories | E6: Completeness | F6: Required timestamps | G6: postgresql/intermediate/tests/Test_categories.sql (TEST 5) | H6: 0 rows | I6: 0 rows | J6: Pass | K6: 30/09/2026
A7: UT-006 | B7: Unit | C7: Intermediate | D7: intermediate.customers | E7: Completeness | F7: Null customer ids | G7: postgresql/intermediate/tests/Test_customers.sql (TEST 1) | H7: 0 rows | I7: 0 rows | J7: Pass | K7: 30/09/2026
A8: UT-007 | B8: Unit | C8: Intermediate | D8: intermediate.customers | E8: Uniqueness | F8: Duplicate customer ids and email | G8: postgresql/intermediate/tests/Test_customers.sql (TEST 2) | H8: 0 rows | I8: 0 rows | J8: Pass | K8: 30/09/2026
A9: UT-008 | B9: Unit | C9: Intermediate | D9: intermediate.customers | E9: Completeness | F9: Required fields | G9: postgresql/intermediate/tests/Test_customers.sql (TEST 3) | H9: 0 rows | I9: 0 rows | J9: Pass | K9: 30/09/2026
A10: UT-009 | B10: Unit | C10: Intermediate | D10: intermediate.customers | E10: Domain / allowed values | F10: Gender validation | G10: postgresql/intermediate/tests/Test_customers.sql (TEST 4) | H10: 0 rows | I10: 0 rows | J10: Pass | K10: 30/09/2026
A11: UT-010 | B11: Unit | C11: Intermediate | D11: intermediate.customers | E11: Consistency | F11: Timestamp validation | G11: postgresql/intermediate/tests/Test_customers.sql (TEST 5) | H11: 0 rows | I11: 0 rows | J11: Pass | K11: 30/09/2026
A12: UT-011 | B12: Unit | C12: Intermediate | D12: intermediate.customers | E12: Business rule | F12: Customer business rules | G12: postgresql/intermediate/tests/Test_customers.sql (TEST 6) | H12: 0 rows | I12: 0 rows | J12: Pass | K12: 30/09/2026
A13: UT-012 | B13: Unit | C13: Intermediate | D13: intermediate.order_items | E13: Uniqueness | F13: Duplicate order item ids | G13: postgresql/intermediate/tests/Test_order_items.sql (TEST 1) | H13: 0 rows | I13: 0 rows | J13: Pass | K13: 30/09/2026
... A21: UT-020 | B21: Unit | C21: Intermediate | D21: intermediate.order_items | E21: Reconciliation | F21: Order total reconciliation | G21: postgresql/intermediate/tests/Test_order_items.sql (TEST 9) | H21: 0 rows | I21: 0 rows | J21: Pass | K21: 30/09/2026
A22: UT-021 | B22: Unit | C22: Intermediate | D22: intermediate.orders | E22: Uniqueness | F22: Duplicate order ids | G22: postgresql/intermediate/tests/Test_orders.sql (TEST 1) | H22: 0 rows | I22: 0 rows | J22: Pass | K22: 30/09/2026 | L22: S7
A23: UT-022 | B23: Unit | C23: Intermediate | D23: intermediate.orders | E23: Completeness | F23: Required fields | G23: postgresql/intermediate/tests/Test_orders.sql (TEST 2) | H23: 0 rows | I23: 0 rows | J23: Pass | K23: 30/09/2026 | L23: S7
A24: UT-023 | B24: Unit | C24: Intermediate | D24: intermediate.orders | E24: Domain / allowed values | F24: Order status validation | G24: postgresql/intermediate/tests/Test_orders.sql (TEST 3) | H24: 0 rows | I24: 0 rows | J24: Pass | K24: 30/09/2026 | L24: S7
A25: UT-024 | B25: Unit | C25: Intermediate | D25: intermediate.orders | E25: Domain / allowed values | F25: Payment status validation | G25: postgresql/intermediate/tests/Test_orders.sql (TEST 4) | H25: 0 rows | I25: 0 rows | J25: Pass | K25: 30/09/2026 | L25: S7
A26: UT-025 | B26: Unit | C26: Intermediate | D26: intermediate.orders | E26: Reconciliation | F26: Order total validation | G26: postgresql/intermediate/tests/Test_orders.sql (TEST 5) | H26: 0 rows | I26: 0 rows | J26: Pass | K26: 30/09/2026 | L26: S7
A27: UT-026 | B27: Unit | C27: Intermediate | D27: intermediate.orders | E27: Consistency | F27: Timestamp validation | G27: postgresql/intermediate/tests/Test_orders.sql (TEST 6) | H27: 0 rows | I27: 0 rows | J27: Pass | K27: 30/09/2026 | L27: S7
A28: UT-027 | B28: Unit | C28: Intermediate | D28: intermediate.orders | E28: Business rule | F28: Customer business rules | G28: postgresql/intermediate/tests/Test_orders.sql (TEST 7) | H28: 0 rows | I28: 0 rows | J28: Pass | K28: 30/09/2026 | L28: S7
A29: UT-028 | B29: Unit | C29: Intermediate | D29: intermediate.orders | E29: Business rule | F29: Company business rule | G29: postgresql/intermediate/tests/Test_orders.sql (TEST 8) | H29: 0 rows | I29: 0 rows | J29: Pass | K29: 30/09/2026 | L29: S7
A30: UT-029 | B30: Unit | C30: Intermediate | D30: intermediate.orders | E30: Business rule | F30: Marketing lead relationship | G30: postgresql/intermediate/tests/Test_orders.sql (TEST 9) | H30: 0 rows | I30: 0 rows | J30: Pass | K30: 30/09/2026 | L30: S7
A31: UT-030 | B31: Unit | C31: Intermediate | D31: intermediate.orders | E31: Business rule | F31: Order item relationship | G31: postgresql/intermediate/tests/Test_orders.sql (TEST 10) | H31: 0 rows | I31: 0 rows | J31: Pass | K31: 30/09/2026 | L31: S7
A32: UT-031 | B32: Unit | C32: Intermediate | D32: intermediate.orders | E32: Reconciliation | F32: Order total reconciliation | G32: postgresql/intermediate/tests/Test_orders.sql (TEST 11) | H32: 0 rows | I32: 0 rows | J32: Pass | K32: 30/09/2026 | L32: S7
A33: UT-032 | B33: Unit | C33: Intermediate | D33: intermediate.products | E33: Completeness | F33: Null product ids | G33: postgresql/intermediate/tests/Test_products.sql (TEST 1) | H33: 0 rows | I33: 0 rows | J33: Pass | K33: 30/09/2026
A34: UT-033 | B34: Unit | C34: Intermediate | D34: intermediate.products | E34: Uniqueness | F34: Duplicate product ids | G34: postgresql/intermediate/tests/Test_products.sql (TEST 2) | H34: 0 rows | I34: 0 rows | J34: Pass | K34: 30/09/2026
A35: UT-034 | B35: Unit | C35: Intermediate | D35: intermediate.products | E35: Uniqueness | F35: Duplicate skus | G35: postgresql/intermediate/tests/Test_products.sql (TEST 3) | H35: 0 rows | I35: 0 rows | J35: Pass | K35: 30/09/2026
A36: UT-035 | B36: Unit | C36: Intermediate | D36: intermediate.products | E36: Completeness | F36: Required fields | G36: postgresql/intermediate/tests/Test_products.sql (TEST 4) | H36: 0 rows | I36: 0 rows | J36: Pass | K36: 30/09/2026
A37: UT-036 | B37: Unit | C37: Intermediate | D37: intermediate.products | E37: Referential integrity | F37: Product → category | G37: postgresql/intermediate/tests/Test_products.sql (TEST 5) | H37: 0 rows | I37: 0 rows | J37: Pass | K37: 30/09/2026
A38: UT-037 | B38: Unit | C38: Intermediate | D38: intermediate.products | E38: Business rule | F38: Price validation | G38: postgresql/intermediate/tests/Test_products.sql (TEST 6) | H38: 0 rows | I38: 0 rows | J38: Pass | K38: 30/09/2026
A39: UT-038 | B39: Unit | C39: Intermediate | D39: intermediate.products | E39: Consistency | F39: Timestamp validation | G39: postgresql/intermediate/tests/Test_products.sql (TEST 7) | H39: 0 rows | I39: 0 rows | J39: Pass | K39: 30/09/2026
A40: UT-039 | B40: Unit | C40: Intermediate | D40: intermediate.suppliers | E40: Completeness | F40: Null supplier ids | G40: postgresql/intermediate/tests/Test_suppliers.sql (TEST 1) | H40: 0 rows | I40: 0 rows | J40: Pass | K40: 30/09/2026
A41: UT-040 | B41: Unit | C41: Intermediate | D41: intermediate.suppliers | E41: Uniqueness | F41: Duplicate supplier ids | G41: postgresql/intermediate/tests/Test_suppliers.sql (TEST 2) | H41: 0 rows | I41: 0 rows | J41: Pass | K41: 30/09/2026
A42: UT-041 | B42: Unit | C42: Intermediate | D42: intermediate.suppliers | E42: Uniqueness | F42: Duplicate emails | G42: postgresql/intermediate/tests/Test_suppliers.sql (TEST 3) | H42: 0 rows | I42: 0 rows | J42: Pass | K42: 30/09/2026
A43: UT-042 | B43: Unit | C43: Intermediate | D43: intermediate.suppliers | E43: Completeness | F43: Required fields | G43: postgresql/intermediate/tests/Test_suppliers.sql (TEST 4) | H43: 0 rows | I43: 0 rows | J43: Pass | K43: 30/09/2026
A44: UT-043 | B44: Unit | C44: Intermediate | D44: intermediate.suppliers | E44: Referential integrity | F44: Supplier → company | G44: postgresql/intermediate/tests/Test_suppliers.sql (TEST 5) | H44: 0 rows | I44: 0 rows | J44: Pass | K44: 30/09/2026
... A71: UT-070 | B71: Unit | C71: Intermediate | D71: intermediate.supplier_product_mapping | E71: Consistency | F71: Timestamp validation | G71: postgresql/intermediate/tests/Tests_supplier_product_mapping.sql (TEST 8) | H71: 0 rows | I71: 0 rows | J71: Pass | K71: 30/09/2026
A72: UT-071 | B72: Unit | C72: Warehouse | D72: warehouse.dim_companies | E72: Reconciliation | F72: Baseline row counts | G72: postgresql/warehouse/tests/dim_companies_tests.sql (TEST 1) | H72: current rows = distinct companies | I72: 2,505 rows, 2,500 companies, 2,500 current, 5 historical | J72: Pass | K72: 30/09/2026 | L72: S10
A73: UT-072 | B73: Unit | C73: Warehouse | D73: warehouse.dim_companies | E73: SCD2 integrity | F73: No company has multiple current versions | G73: postgresql/warehouse/tests/dim_companies_tests.sql (TEST 2) | H73: 0 rows | I73: 0 rows | J73: Pass | K73: 30/09/2026 | L73: S10
...

Sheet Integration_Tests
A1: Test ID | B1: Level | C1: Layer | D1: Object Under Test | E1: Test Type | F1: Description | G1: Test Script / File | H1: Expected Result | I1: Actual Result | J1: Status | K1: Executed On | L1: Evidence | M1: Defect ID
A2: IT-01 | B2: Integration | C2: Source, Intermediate | D2: Source -> intermediate completeness | E2: Cross-layer reconciliation | F2: Every source record (8 tables + 2 files) is in intermediate or in rejected_records | G2: postgresql/tests/integration_tests.sql (IT-01, manual count) | H2: Every source record (8 tables + 2 files) is in intermediate or in rejected_records | I2: 0 differences (2,258 + 4,517 rejected CSV rows) | J2: Pass | K2: 30/09/2026
A3: IT-02 | B3: Integration | C3: Staging, Intermediate | D3: Staging cleared after a successful run | E3: Cross-layer reconciliation | F3: Every staging row is in intermediate or rejected_records; then all 10 staging tables are empty | G3: postgresql/tests/integration_tests.sql (IT-02) | H3: 0 staging rows after the run | I3: 0 staging rows left | J3: Pass | K3: 30/09/2026
A4: IT-03 | B4: Integration | C4: Intermediate, Warehouse | D4: Intermediate -> warehouse completeness | E4: Cross-layer reconciliation | F4: Row counts equal for 5 dimensions (current rows) and 4 facts | G4: postgresql/tests/integration_tests.sql (IT-03) | H4: Row counts equal for 5 dimensions (current rows) and 4 facts | I4: 0 differences | J4: Pass | K4: 30/09/2026 | L4: S9
A5: IT-04 | B5: Integration | C5: Metadata, Source | D5: CDC watermark correctness | E5: Cross-layer reconciliation | F5: Each of the 8 watermarks = MAX(updated_at) of its source table | G5: postgresql/tests/integration_tests.sql (IT-04) | H5: Each of the 8 watermarks = MAX(updated_at) of its source table | I5: 8 of 8 watermarks correct | J5: Pass | K5: 30/09/2026
A6: IT-05 | B6: Integration | C6: Source, Intermediate, Warehouse | D6: SCD Type 2 history after CDC updates | E6: Cross-layer reconciliation | F6: Changed companies have a closed old version whose end = start of the new version; one current version each | G6: postgresql/tests/integration_tests.sql (IT-05) | H6: Changed companies have a closed old version whose end = start of the new version; one current version each | I6: 5 companies with history, 0 gaps/overlaps | J6: Pass | K6: 30/09/2026 | L6: S10
A7: IT-06 | B7: Integration | C7: Warehouse | D7: Point-in-time company lookup | E7: Cross-layer reconciliation | F7: Every order points to the company version valid at order time | G7: postgresql/tests/integration_tests.sql (IT-06) | H7: Every order points to the company version valid at order time | I7: 0 orders outside their version's validity | J7: Pass | K7: 30/09/2026
A8: IT-07 | B8: Integration | C8: Warehouse | D8: Order header vs order lines | E8: Cross-layer reconciliation | F8: fact_orders.order_total = SUM(line_total) and item_count = number of lines | G8: postgresql/tests/integration_tests.sql (IT-07) | H8: fact_orders.order_total = SUM(line_total) and item_count = number of lines | I8: 0 mismatching orders | J8: Pass | K8: 30/09/2026
A9: IT-08 | B9: Integration | C9: Intermediate, Warehouse | D9: Lead to order link (cross-source) | E9: Cross-layer reconciliation | F9: Converted leads carry their order_id; every order's lead_id exists in fact_leads | G9: postgresql/tests/integration_tests.sql (IT-08) | H9: Converted leads carry their order_id; every order's lead_id exists in fact_leads | I9: 0 inconsistent leads, 0 orders with unknown lead | J9: Pass | K9: 30/09/2026
A10: IT-09 | B10: Integration | C10: All | D10: End-to-end incremental run | E10: Cross-layer reconciliation | F10: Latest run of all 5 stages has status 'completed' | G10: postgresql/tests/integration_tests.sql (IT-09) | H10: Latest run of all 5 stages has status 'completed' | I10: 5 of 5 stages completed | J10: Pass | K10: 30/09/2026
A11: IT-10 | B11: Integration | C11: Warehouse | D11: Idempotent re-run of warehouse loads | E11: Cross-layer reconciliation | F11: Re-running the four load_fact_*.sql scripts leaves all fact row counts unchanged | G11: Re-run of load_fact_*.sql (30/09/2026) | H11: Re-running the four load_fact_*.sql scripts leaves all fact row counts unchanged | I11: 0 rows changed by each MERGE; counts and value totals identical (orders 156,678, lines 470,263, web logs 296,703, leads 148,358) | J11: Pass | K11: 30/09/2026 | L11: S11

Sheet KPI_Validation
A1: Test ID | B1: KPI ID | C1: KPI | D1: Validation Method | E1: Query / Source | F1: Expected | G1: Actual | H1: Status | I1: Executed On | J1: Evidence
A2: KV-01 | B2: KPI-01 | C2: Monthly Revenue Trend | D2: Sum of monthly net revenue = non-cancelled line revenue of the same 23 complete months | E2: SELECT SUM(net_revenue) FROM marts.vw_monthly_revenue_trend | F2: 4,400,274,489.23 | G2: 4,400,274,489.23 | H2: Pass | I2: 30/09/2026 | J2: S13
A3: KV-02 | B3: KPI-02 | C3: Revenue by Company | D3: Sum of company gross revenue = SUM(quantity x unit_price) of buyer, non-cancelled lines | E3: SELECT SUM(gross_revenue) FROM marts.vw_revenue_by_company | F3: 5,133,378,828.46 | G3: 5,133,378,828.46 | H3: Pass | I3: 30/09/2026
A4: KV-03 | B4: KPI-03 | C4: Revenue by Product | D4: Sum of product net revenue = total net revenue; one row per product | E4: SELECT SUM(net_revenue) FROM marts.vw_revenue_by_product | F4: 4,621,200,118.84 | G4: 4,621,200,118.84 | H4: Pass | I4: 30/09/2026
A5: KV-04 | B5: KPI-04 | C5: Gross Margin Analysis | D5: Sum of gross profit = SUM(line_total - quantity x supplier_price) | E5: SELECT SUM(gross_profit) FROM marts.vw_gross_margin_analysis | F5: 954,597,910.13 | G5: 954,597,910.13 | H5: Pass | I5: 30/09/2026
A6: KV-05 | B6: KPI-05 | C6: Customer Lifetime Value | D6: Sum of company total spend = net revenue of buyer companies | E6: SELECT SUM(total_spend) FROM marts.vw_customer_lifetime_value | F6: 4,621,200,118.84 | G6: 4,621,200,118.84 | H6: Pass | I6: 30/09/2026
A7: KV-06 | B7: KPI-06 | C7: Customer Activity | D7: Repeat purchase rate recomputed from fact_orders | E7: SELECT MAX(repeat_purchase_rate_pct) FROM marts.vw_customer_activity | F7: 60.31 | G7: 60.31 | H7: Pass | I7: 30/09/2026
A8: KV-07 | B8: KPI-07 | C8: Geographic Sales | D8: Sum of revenue by location = total net revenue | E8: SELECT SUM(revenue_by_location) FROM marts.vw_geographic_sales | F8: 4,621,200,118.84 | G8: 4,621,200,118.84 | H8: Pass | I8: 30/09/2026
A9: KV-08 | B9: KPI-08 | C9: Traffic by Device | D9: Sum of sessions = distinct (session, device) of non-bot requests | E9: SELECT SUM(total_sessions) FROM marts.vw_traffic_by_device | F9: 281,911 | G9: 281,911 | H9: Pass | I9: 30/09/2026
A10: KV-09 | B10: KPI-09 | C10: Geographic Web Traffic | D10: Countries in the view = countries in non-bot web logs | E10: SELECT COUNT(DISTINCT country) FROM marts.vw_geographic_web_traffic | F10: 3 | G10: 3 | H10: Pass | I10: 30/09/2026
A11: KV-10 | B11: KPI-10 | C11: Web Activity Quality | D11: Sum of requests by endpoint = all web-log rows; errors = status 400-599 | E11: SELECT SUM(total_requests)::text || ' / ' || SUM(error_4xx+error_5xx)::text FROM marts.vw_web_activity_quality | F11: 296703 / 59348 | G11: 296703 / 59348 | H11: Pass | I11: 30/09/2026
A12: KV-11 | B12: KPI-11 | C12: Lead Conversion Funnel | D12: Sum of converted leads = leads with conversion_status 'Converted' | E12: SELECT SUM(converted_leads) FROM marts.vw_lead_conversion_funnel | F12: 6,044 | G12: 6,044 | H12: Pass | I12: 30/09/2026
A13: KV-12 | B13: KPI-12 | C13: Lead Quality vs Order Value | D13: Converted-lead count = independent join count; correlation within -1..1 | E13: SELECT converted_leads::text || ' | r=' || lead_score_order_value_correlation::text FROM marts.vw_lead_quality_vs_order_value | F13: 5748 | r=0.0071 | G13: 5748 | r=0.0071 | H13: Pass | I13: 30/09/2026
A14: KV-13 | B14: KPI-13 | C14: Supplier Revenue | D14: Sum of supplier revenue = total net revenue; shares add up to 100 % | E14: SELECT SUM(total_revenue)::text || ' | ' || ROUND(SUM(revenue_share_pct))::text || '%' FROM marts.vw_supplier_revenue | F14: 4621200118.84 | 100% | G14: 4621200118.84 | 100% | H14: Pass | I14: 30/09/2026
... A16: KV-15 | B16: KPI-15 | C16: Pipeline Execution Metrics | D16: One row per pipeline in the run log; data freshness / watermark lag populated | E16: SELECT COUNT(*)::text || ' rows, ' || COUNT(data_freshness)::text || ' with freshness' FROM marts.vw_pipeline_execution_metrics | F16: 5 rows, 5 with freshness | G16: 5 rows, 5 with freshness | H16: Pass | I16: 30/09/2026

Sheet Defect_Log
A1: Defect ID | B1: Test ID | C1: Found In | D1: Description | E1: Severity | F1: Status | G1: Root Cause | H1: Fix / Commit | I1: Closed On
A2: D-01 | B2: UT-046..UT-050 | C2: Test_web_logs.sql | D2: A leftover query at the top returned every web log | E2: Low | F2: Closed | G2: Debug query left in the file | H2: Query removed | I2: 30/09/2026
A3: D-02 | B3: UT-051..UT-062 | C3: Tests_companies.sql | D3: A stray semicolon split one test in two | E3: Low | F3: Closed | G3: Typo | H3: Semicolon removed | I3: 30/09/2026
A4: D-03 | B4: UT-004, UT-005 | C4: Test_categories.sql | D4: Missing semicolon; TEST 5 checked companies instead of categories | E4: Low | F4: Closed | G4: Copy-paste error | H4: Semicolon added; table corrected | I4: 30/09/2026
A5: D-04 | B5: UT-081 | C5: dim_companies_tests.sql (TEST 11) | D5: Checked the current SCD2 version instead of the first one; failed after a company change | E5: Medium | F5: Closed | G5: Wrong version compared | H5: Compare MIN(effective_start_date) per company | I5: 30/09/2026
A6: D-05 | B6: KV-06 | C6: marts.vw_customer_activity (KPI 6) | D6: 449 customers without a country | E6: Medium | F6: Closed | G6: Extra is_current filter on an as-of key | H6: Join on company_key only | I6: 30/09/2026
A7: D-06 | B7: KV-01 | C7: marts.vw_monthly_revenue_trend (KPI 1) | D7: Future and partial months included; 'Latest Net MoM %' card showed '--' | E7: Medium | F7: Closed | G7: dim_date runs 6 months ahead | H7: Complete months only; month_num / month_start added | I7: 30/09/2026
A8: D-07 | B8: - | C8: Data generators | D8: Daily data back-dated; volume ramp hid seasonality; no failed/refunded payments | E8: High | F8: Closed | G8: Customer picked before the order date | H8: Date first, then customer; daily data dated today; payment by order status | I8: 30/09/2026
